<?xml version="1.0"?>
<robot name="cylinder_robot">
  <!-- Base link (robot body) -->
  <link name="base_link">
	  <visual>
		  <geometry>
			  <cylinder length="0.3" radius="0.15"/>
			</geometry>
			<material name="blue">
				<color rgba="0 0 1 1"/>
			</material>
		</visual>
    
    <collision>
	    <geometry>
		    <cylinder length="0.3" radius="0.15"/>
		  </geometry>
		</collision>
    
    <inertial>
	    <mass value="5.0"/>
	    <inertia
	      ixx="0.05" ixy="0.0" ixz="0.0"
	      iyy="0.05" iyz="0.0"
	      izz="0.05"/>
	    </inertial>
	</link>
  
  
  <!-- Left wheel -->
  <link name="left_wheel">
	  <visual>
		  <geometry>
			  <cylinder length="0.05" radius="0.05"/>
			</geometry>
			<material name="black">
				<color rgba="0 0 0 1"/>
			</material>
		</visual>
    
    <collision>
	    <geometry>
		    <cylinder length="0.05" radius="0.05"/>
		  </geometry>
		</collision>
    
    <inertial>
	    <mass value="0.5"/>
	    <inertia
		    ixx="0.001" ixy="0.0" ixz="0.0"
		    iyy="0.001" iyz="0.0"
		    izz="0.001"/>
		</inertial>
	</link>
  
  
  <!-- Right wheel -->
  <link name="right_wheel">
	  <visual>
		  <geometry>
			  <cylinder length="0.05" radius="0.05"/>
			</geometry>
			<material name="black"/>
		</visual>
    
    <collision>
	    <geometry>
		    <cylinder length="0.05" radius="0.05"/>
		  </geometry>
		</collision>
    
    <inertial>
	    <mass value="0.5"/>
	    <inertia
		    ixx="0.001" ixy="0.0" ixz="0.0"
		    iyy="0.001" iyz="0.0"
		    izz="0.001"/>
		 </inertial>
	</link>
  
  
  <!-- Joints -->
  <joint name="left_wheel_joint" type="continuous">
	  <parent link="base_link"/>
	  <child link="left_wheel"/>
	  <origin xyz="0 0.15 -0.125" rpy="1.5708 0 3.1416"/>
	  <axis xyz="0 0 1"/>
	</joint>
  
  <joint name="right_wheel_joint" type="continuous">
	  <parent link="base_link"/>
	  <child link="right_wheel"/>
	  <origin xyz="0 -0.15 -0.125" rpy="1.5708 0 3.1416"/>
	  <axis xyz="0 0 1"/>
	</joint>
	
	
<!-- Gazebo differential drive plugin -->
<gazebo>
	<plugin name="diff_drive" filename="libgazebo_ros_diff_drive.so">
    <!-- Wheel joints -->
    <left_joint>left_wheel_joint</left_joint>
    <right_joint>right_wheel_joint</right_joint>
    
    <!-- Geometry -->
    <wheel_separation>0.30</wheel_separation>
    <wheel_diameter>0.10</wheel_diameter>
    
    <!-- Output -->
    <publish_odom>true</publish_odom>
    <publish_odom_tf>true</publish_odom_tf>    <publish_wheel_tf>false</publish_wheel_tf>
    
    <!-- Frames -->
    <odometry_frame>odom</odometry_frame>
    <robot_base_frame>base_link</robot_base_frame>
    
    <!-- ROS interface -->
    <command_topic>cmd_vel</command_topic>
    <odometry_topic>odom</odometry_topic>
  
  </plugin>
</gazebo>

</robot>
